Workbook
Name APLICA: Tabla3[APLICA]
Name APLICA: Tabla3[APLICA]
Name APLICA: Tabla3[APLICA]
Name APLICA: Tabla3[APLICA]
Name APLICA: [1]!Tabla3[APLICA]
Name APLICA: [1]!Tabla3[APLICA]
Name APLICA: [1]!Tabla3[APLICA]
Name APLICA: [1]!Tabla3[APLICA]
Name APLICA: [1]!Tabla3[APLICA]
Name APLICA: Tabla3[APLICA]
Name APLICA: Tabla3[APLICA]
Name APLICA: [2]!Tabla3[APLICA]
Name APLICA: Tabla3[APLICA]
Name CUMPLIMIENTO: Tabla1[CUMPLIMIENTO]
Name CUMPLIMIENTO: Tabla1[CUMPLIMIENTO]
Name CUMPLIMIENTO: Tabla1[CUMPLIMIENTO]
Name CUMPLIMIENTO: Tabla1[CUMPLIMIENTO]
Name CUMPLIMIENTO: [1]!Tabla13[CUMPLIMIENTO]
Name CUMPLIMIENTO: [1]!Tabla13[CUMPLIMIENTO]
Name CUMPLIMIENTO: [1]!Tabla13[CUMPLIMIENTO]
Name CUMPLIMIENTO: [1]!Tabla13[CUMPLIMIENTO]
Name CUMPLIMIENTO: [1]!Tabla13[CUMPLIMIENTO]
Name CUMPLIMIENTO: Tabla1[CUMPLIMIENTO]
Name CUMPLIMIENTO: [3]!Tabla13[CUMPLIMIENTO]
Name CUMPLIMIENTO: [3]!Tabla13[CUMPLIMIENTO]
Name CUMPLIMIENTO: [3]!Tabla13[CUMPLIMIENTO]
Name CUMPLIMIENTO: Tabla1[CUMPLIMIENTO]
Name CUMPLIMIENTO: [2]!Tabla13[CUMPLIMIENTO]
Name CUMPLIMIENTO: Tabla1[CUMPLIMIENTO]

Sheet ÍNDICE
B2: GERENCIA DE SEGURIDAD Y SALUD OCUPACIONAL - CHUQUICAMATA
B4: Empresa | E4: : | J4: % GENERAL
B5: N° y Nombre de contrato y/u ODS | E5: : | J5: =IFERROR(AVERAGEIF(H12:H41,">=0"),"NO APLICA") -> 0.3375
B7: Gerencia o Dirección | E7: :
B8: Gerente de Area | E8: :
B9: Líder de gestión del cambio | E9: :
A11: ÍNDICE RIESGOS DE FATALIDAD | G11: ¿APLICA? | H11: % CUMPLIMIENTO | I11: IR AL RF | J11: DUEÑO DEL RIESGO
A12: RF01 | B12: ENERGÍA ELÉCTRICA | G12: SÍ | H12: ='RF01'!I7 -> 0.9 | I12: IR AL RF01
A13: RF02 | B13: TRABAJO EN ALTURA | G13: SÍ | H13: ='RF02'!I7 -> 0 | I13: IR AL RF02
A14: RF03 | B14: MANIOBRAS DE IZAJE | G14: SÍ | H14: ='RF03'!I7 -> 0 | I14: IR AL RF03
A15: RF04 | B15: LIBERACIÓN DESCONTROLADA DE ENERGÍAS | G15: SÍ | H15: ='RF04'!I7 -> 0 | I15: IR AL RF04
A16: RF05 | B16: CAÍDA DE ROCAS EN MINA RAJO | G16: SÍ | H16: ='RF05'!I7 -> 0 | I16: IR AL RF05
A17: RF06 | B17: INCENDIO | G17: SÍ | H17: ='RF06'!I7 -> 0.4 | I17: IR AL RF06
A18: RF07 | B18: SUSTANCIAS PELIGROSAS | G18: SÍ | H18: ='RF07'!I7 -> 0.4 | I18: IR AL RF07
A19: RF08 | B19: TRONADURAS Y EXPLOSIVOS | G19: SÍ | H19: ='RF08'!I7 -> 1 | I19: IR AL RF08
A20: RF09 | B20: PARTES MÓVILES | G20: SÍ | H20: ='RF09'!I7 -> #DIV/0! | I20: IR AL RF09
A21: RF10 | B21: VEHÍCULOS | G21: SÍ | H21: ='RF10'!I7 -> #DIV/0! | I21: IR AL RF10
A22: RF11 | B22: ESPACIOS CONFINADOS | G22: SÍ | H22: ='RF11'!I7 -> #DIV/0! | I22: IR AL RF11
A23: RF12 | B23: MATERIALES FUNDIDOS | G23: SÍ | H23: ='RF12'!I7 -> #DIV/0! | I23: IR AL RF12
A24: RF13 | B24: CAÍDA DE OBJETOS | G24: SÍ | H24: ='RF13'!I7 -> #DIV/0! | I24: IR AL RF13
A25: RF14 | B25: OPERACIÓN FERROVIARIA | G25: SÍ | H25: ='RF14'!I7 -> #DIV/0! | I25: IR AL RF14
A26: RF15 | B26: AVALANCHA Y ALUDES | G26: NO | H26: NO APLICA | I26: IR AL RF15
A27: RF16 | B27: VACIADOS, CHIMENEAS Y PIQUES | G27: SÍ | H27: ='RF16'!I7 -> #DIV/0! | I27: IR AL RF16
A28: RF17 | B28: MATERIAL HUMEDO | G28: NO | H28: NO APLICA | I28: IR AL RF17
A29: RF18 | B29: PLANCHONEO | G29: SÍ | H29: ='RF18'!I7 -> #DIV/0! | I29: IR AL RF18
A30: RF19 | B30: ESTALLIDO DE ROCA | G30: NO | H30: NO APLICA | I30: IR AL RF19
A31: RF20 | B31: SÍLICE | G31: SÍ | H31: ='RF20'!I7 -> #DIV/0! | I31: IR AL RF20
A32: RF21 | B32: ARSÉNICO | G32: SÍ | H32: ='RF21'!I7 -> #DIV/0! | I32: IR AL RF21
A33: RF22 | B33: COLAPSO ESTRUCTURAL DE PASILLOS, PISOS Y BARANDAS | G33: SÍ | I33: IR AL RF22
A34: RF23 | B34: COLAPSO ESTRUCTURAL DEL MACIZO ROCOSO | G34: SÍ | H34: ='RF23'!I7 -> #DIV/0! | I34: IR AL RF23
A35: RF24 | B35: TALUDES | G35: SÍ | H35: ='RF24'!I7 -> #DIV/0! | I35: IR AL RF24
A36: RF25 | B36: EQUIPOS MINEROS E INDUSTRIALES | G36: SÍ | H36: ='RF25'!I7 -> #DIV/0! | I36: IR AL RF25
A37: RF26 | B37: EQUIPOS AUTÓNOMOS | G37: NO | H37: NO APLICA | I37: IR AL RF26
A38: RF27 | B38: ATROPELLO | G38: SÍ | H38: ='RF27'!I7 -> #DIV/0! | I38: IR AL RF27
A39: RF28 | B39: CAVING | G39: SÍ | H39: ='RF28'!I7 -> #DIV/0! | I39: IR AL RF28
A40: RF29 | B40: CAIDA A CUERPOS LIQUIDOS | G40: SÍ | H40: ='RF29'!I7 -> #DIV/0! | I40: IR AL RF29
A41: RF30 | B41: TIRO Y ARRASTRE | G41: SÍ | I41: IR AL RF30
B43: RIESGOS DE FATALIDAD (BOWTIE) APLICABLES | G43: =COUNTIF(G12:G41,"SÍ") -> 26
B44: RIESGOS DE FATALIDAD (BOWTIE) "NO" APLICABLES | G44: =COUNTIF(G12:G41,"NO") -> 4

Sheet Listas desplegables
C3: CUMPLIMIENTO | E3: APLICA
C4: N/A | E4: SÍ
C5: 0 | E5: NO
C6: 0.1
C7: 0.2
C8: 0.3
C9: 0.4
C10: 0.5
C11: 0.6
C12: 0.7
C13: 0.8
C14: 0.9
C15: 1

Sheet RF01
B2: GERENCIA DE SEGURIDAD Y SALUD OCUPACIONAL - CHUQUICAMATA
B4: LISTADO DE AUTODIAGNÓSTICO RIESGO DE FATALIDAD N°01: ENERGÍA ELÉCTRICA
B6: ELEMENTOS DEL CONTROL | I6: CUMPLIMIENTO GENERAL
I7: =AVERAGEIF(I14:I67,"<>N/A") -> 0.9
B10: Alcance | C10: Interacción entre energía eléctrica y las personas. Esto puede ocurrir en actividades de operación, mantención, servicios, proyectos en donde se puedan observar exposición a AT - BT (AT > 1000 V y BT <1000 V CA). • Salas eléctricas, Subestaciones eléctricas, Equipos mineros eléctricos (móviles y semi móviles). • Herramientas eléctricas, líneas de media y alta tensión. • Intervención de equipos y sistemas eléctricos energizados. • Generadores, exposición a CC circuitos, bancos de baterías. • También incluye equipos de fuente de alimentación, cable de transmisión eléctrica y electrodos
B11: Exclusión | C11: Este evento considera como exclusión los siguientes escenarios: • Trabajos en torres de alta tensión con líneas energizadas. (maniobras de operación, mediciones, pruebas y seguimiento de fallas).
B13: RIESGO FATALIDAD | C13: CONTROL CRÍTICO | D13: NOMBRE DEL CONTROL CRÍTICO | E13: OBJETIVO | F13: REQUISITO | G13: MONITOREO | H13: EVIDENCIA | I13: CUMPLIMIENTO | J13: OBSERVACIONES | K13: FECHA IMPLEMENTACIÓN | L13: PLAN MITIGADOR
B14: RF01 | C14: CCP1 | D14: Personal acreditado para trabajos eléctricos | E14: Asegurar que toda persona que realice intervenciones en sistemas eléctricos que puedan estar energizados cuente con calificación y autorización formal vigente (Licencia Eléctrica), conforme a los reglamentos corporativos y divisionales. | F14: Trazabilidad de requisitos para la autorización de intervención de sistemas eléctricos. | G14: Semestral | H14: Registro del personal que se encuentra autorizado a intervenir sistemas eléctricos, con sus requisitos en cumplimiento según lo definido en SIG0-I-013. | I14: 0.9
F15: Autorización formal a través de licencia eléctrica. | G15: Trimestral | H15: Credencial física o digital disponible, acorde a las actividades que realiza el personal, según lo definido en SIG0-I-013. | I15: N/A
F16: Auditoría al sistema de autorización. | G16: Anual | H16: Reporte de auditoría que verifica la operatividad y actualización del sistema de autorización, con existencia de respaldos correspondientes y en cumplimiento del SIGO-I-013. | I16: N/A
B17: RF01 | C17: CCP2 | D17: Acceso restringido a equipos e instalaciones eléctricas | E17: Asegurar que únicamente personal autorizado acceda a equipos e instalaciones eléctricas, mediante barreras físicas y sistemas de custodia y/o control de acceso, según aplique. | F17: Procedimiento de ingreso a instalaciones eléctricas | G17: Anual | H17: Procedimiento vigente que define el mecanismo de custodia de instalaciones eléctricas y el proceso para acceder a ellas. | I17: N/A
F18: Integridad de barreras físicas. | G18: Semestral | H18: Inspección documentada que verifica el estado operativo de puertas, cierres y candados de equipos e instalaciones eléctricas. | I18: N/A
F19: Señalización de advertencia. | G19: Trimestral | H19: Verificación en terreno de letreros de advertencia visibles y legibles en equipos e instalaciones eléctricas. | I19: N/A
B20: RF01 | C20: CCP3 | D20: Equipos y herramientas eléctricas verificadas | E20: Asegurar que todo el personal que interviene sistemas eléctricos utilice exclusivamente herramientas e instrumentos que han sido verificados y se encuentran en buenas condiciones. | F20: Verificación de condiciones visibles. | G20: Cada tarea | H20: Lista de verificación en terreno de las herramientas e instrumentos en uso. | I20: N/A
F21: Mantenimiento y calibración de instrumentos. | G21: Semestral | H21: Registro de mantenimiento e inspección para instrumentos de medición y herramientas de maniobra. | I21: N/A
F22: Protecciones en herramientas eléctricas. | G22: Semestral | H22: Registro de inspección que verifica la integridad del sistema de puesta a tierra (tercer pin, cable) de las herramientas eléctricas (ej. generador, tablero móvil). | I22: N/A
B23: RF01 | C23: CCP4 | D23: Intervención de equipos en condición eléctricamente segura | E23: Garantizar que antes de intervenir un sistema eléctrico este se encuentre en condición eléctricamente segura, mediante la aplicación de las 5 Reglas de Oro del Electricista. | F23: Procedimiento de aislación y bloqueo de energía eléctrica. | G23: Anual | H23: Procedimiento vigente que define el proceso de aislación y bloqueo, aplicable para energía eléctrica y registro de instrucción del documento al personal. | I23: N/A
F24: Proceso de solicitud de desconexión e intervención en sistemas de media tensión. | G24: Cada vez | H24: Documento (SODI) en físico o digital autorizado, según lo definido en SIG0-I-012. | I24: N/A
F25: Identificación y aislación. | G25: Cada vez | H25: Registro de identificación de los puntos de aislación y puntos de bloqueo, según mapas de bloqueo o diagramas disponibles para este fin. | I25: N/A
F26: Bloqueo y advertencia. | G26: Cada vez | H26: Verificación en terreno de los dispositivos de bloqueo y advertencia instalados y rotulados adecuadamente. | I26: N/A
F27: Verificación de ausencia de tensión. | G27: Cada vez | H27: Registro de la metodología utilizada para verificar ausencia de tensión y los resultados de prueba. | I27: N/A
F28: Instalación de puesta a tierra temporal. | G28: Cada vez | H28: Verificación en terreno de instalación de puesta a tierra temporal, con lista de verificación del conjunto y en los puntos definidos. | I28: N/A
F29: Segregación del lugar de intervención. | G29: Cada vez | H29: Verificación en terreno de la instalación de barreras (conos con cadenas) y señalización en el lugar de intervención. | I29: N/A
F30: Verificación de prácticas eléctricas. | G30: Anual | H30: Verficación de aplicación de 5 Reglas de Oro, SODI y procedimiento de bloqueo. | I30: N/A
B31: RF01 | C31: CCM1 | D31: Selección y uso de EPP específico para la actividad | E31: Asegurar que todo trabajador que se vea expuesto a riesgo eléctrico seleccione y use correctamente EPP específico y en condiciones, para las actividades a realizar. | F31: Estudio de energía incidental. | G31: Anual | H31: Estudio que determina la energía incidental (cal/cm²), que determina la distancia de seguridad y el EPP específico a utilizar en equipos e instalaciones eléctricas. | I31: N/A
F32: Control de disponibilidad y entrega de elementos de protección personal específicos. | G32: Semestral | H32: Registro de entrega de EPP específicos al personal electricista, de acuerdo con lo definido en el estudio de elementos de protección personal. | I32: N/A
F33: Inspección pre-uso de los elementos de protección personal específicos. | G33: Cada Tarea | H33: Lista de verificación en terreno de los EPP específicos para el arco eléctrico y choque eléctrico en uso. | I33: N/A
B34: RF01 | C34: CCM2 | D34: Protecciones eléctricas en sistemas de alta tensión | E34: Asegurar que los sistemas de protecciones de los sistemas eléctricos, operen adecuadamente para despejar y proteger al personal ante fallas eléctricas. | F34: Plan Matriz de Mantenimiento de Protecciones. | G34: Anual | H34: Plan matriz (ej. SAP) con OTs cerradas de mantenimiento y pruebas funcionales de protecciones (relés, interruptores) según fabricante/norma. | I34: N/A
F35: Estudios Eléctricos Vigentes. | G35: Anual | H35: Estudios de Coordinación de Protecciones y Energía Incidental vigente y disponibles en terreno para consulta. | I35: N/A
F36: Medición de Mallas a Tierra (Instalaciones). | G36: Anual | H36: Informe de medición de resistencia de mallas a tierra y continuidad de puestas a tierra de equipos, vigente (< 1 año). | I36: N/A
F37: Pruebas Funcionales con Trazabilidad. | G37: Anual | H37: Registros de pruebas de protecciones realizadas con instrumentos que poseen trazabilidad vigente. | I37: N/A
F38: Integridad de Infraestructura (Inspección). | G38: Semestral | H38: Registros de inspección (checklist) de condiciones de salas, tableros y S/E (limpieza, orden, integridad física, señalética). | I38: N/A
B40: RIESGO FATALIDAD | C40: CONTROL | D40: NOMBRE DEL CONTROL | E40: REQUISITO | G40: EVIDENCIA | I40: CUMPLIMIENTO | J40: OBSERVACIONES | K40: FECHA IMPLEMENTACIÓN | L40: PLAN MITIGADOR
B41: RF01 | C41: CP1 | D41: Planos unilineales actualizados | E41: Todo trabajo que involucre intervención en sistemas eléctricos debe contar con planos unilineales actualizados, disponibles y legibles en terreno. | G41: A. El supervisor(a) debe asegurar que los planos reflejen la ubicación y características reales de todo el sistema eléctrico. | I41: N/A
G42: B. Los planos deben estar actualizados tras cada modificación en la red eléctrica, con trazabilidad documental | I42: N/A
G43: C. Su disponibilidad debe ser verificada antes de iniciar excavaciones o trabajos de terreno en zonas con riesgo eléctrico | I43: N/A
B44: RF01 | C44: CP2 | D44: Enclavamientos eléctricos operativos | E44: Todos los enclavamientos eléctricos de tableros y equipos deben encontrarse operativos y en condiciones de uso seguro. | G44: A. El supervisor(a) debe verificar en la inspección previa el correcto funcionamiento de enclavamientos para impedir maniobras indebidas o no autorizadas. | I44: N/A
G45: B. Cualquier falla en enclavamientos debe implicar el retiro del equipo del servicio hasta su reparación. | I45: N/A
G46: C. La condición operativa de los enclavamientos debe estar documentada en el programa de mantenimiento eléctrico. | I46: N/A
B47: RF01 | C47: CP3 | D47: Porticos de control de altura para tránsito bajo tendidos eléctricos | E47: En todas las rutas de tránsito bajo tendidos eléctricos de media o alta tensión se deben instalar pórticos de control de altura. | G47: A. Los pórticos deben ubicarse antes de zonas de riesgo, con señalización visible para operadores de equipos de gran altura. | I47: N/A
...

Sheet RF02
B2: GERENCIA DE SEGURIDAD Y SALUD OCUPACIONAL - CHUQUICAMATA
B4: LISTADO DE AUTODIAGNÓSTICO RIESGO DE FATALIDAD N°02: TRABAJO EN ALTURA
B6: ELEMENTOS DEL CONTROL | I6: CUMPLIMIENTO GENERAL
I7: =AVERAGEIF(I14:I60,"<>N/A") -> 0
B10: Alcance | C10: Actividades con potencial de caída desde una altura igual o superior a 1,8 metros, en actividades, tales como: • Trabajos sobre plataformas fijas temporales (como andamios u otras estructuras similares). • Puntos de trabajo sobre equipos. • Trabajos en altura realizados en edificios e instalaciones. • Uso de plataformas móviles (equipos elevadores de personas, manipuladores telescópicos con canastillo / jaula). • Presencia en bordes desprotegidos a una altura mayor a 1,8 metros. • Trabajos realizados sobre escalas que cuenten con plataforma. • Uso de escalas verticales fijas. • Techos inclinados, cualquiera sea el ángulo de inclinación.
B11: Exclusión | C11: • Caída a distinto nivel por colapso estructural. • Aberturas (vanos) por ausencia de grating y/o barandas. • Trabajos verticales (cuerdas, saneamiento de taludes).
B13: RIESGO FATALIDAD | C13: CONTROL CRÍTICO | D13: NOMBRE DEL CONTROL CRÍTICO | E13: OBJETIVO | F13: REQUISITO | G13: MONITOREO | H13: EVIDENCIA | I13: CUMPLIMIENTO | J13: OBSERVACIONES | K13: FECHA IMPLEMENTACIÓN | L13: PLAN MITIGADOR
B14: RC02 | C14: CCP1 | D14: Plataformas y superficies de trabajo estables e íntegras | E14: -Asegurar que las plataformas y superficies de trabajo sean estructuralmente estables, capaces de soportar de manera segura las cargas previstas (personas, equipos, materiales) sin colapsar, cumpliendo todas las normativas aplicables. -Prevenir la falla estructural o la pérdida de estabilidad de las plataformas y superficies durante su uso. | F14: Documentación que Respalda el Diseño, Ingeniería y Componentes | G14: Semestral | H14: Repositorio con: Memorias de cálculo, planos de diseño firmados por personal calificado, certificados de componentes, evidencia de cumplimiento normativo/fabricante, capacidad de carga e informes de verificación visual de componentes vs. diseño. | I14: 0
F15: Evidencias del Correcto Montaje, Instalación y Preparación Inicial | G15: Semanal | H15: -Debe ser realizado por personal capacitado (curso de armado/desarme de andamios, operación de plataformas móviles e instrucción de procedimiento/manual de fabricante) -Verificación de superficie de apoyo, y acta/registro de entrega de plataforma instalada (estable, nivelada y asegurada). | I15: N/A
F16: Registros de Inspecciones y Gestión de Estado Operativo | G16: Cada vez | H16: Registros/evidencia de: Inspecciones pre-uso (checklists firmados), inspecciones periódicas formales (informes firmados), y uso visible y actualizado de tarjetas de estado (Verde/Roja) en plataformas. | I16: N/A
F17: Verificación del Cumplimiento de la Capacidad de Carga de la Plataforma | G17: Cada vez | H17: Evidencia documentada del control de cargas aplicadas a la plataforma (ej. registros de carga, señalética de capacidad máxima) y verificación de que no se excede su capacidad nominal durante el uso (ej. en verificaciones u observaciones en terreno). | I17: N/A
F18: Registros de Mantenimiento de la Plataforma móvil | G18: Anual | H18: Registro de reparaciones o ajustes realizados tras fallas detectadas en inspecciones, con validación previa a su reincorporación al uso. | I18: N/A
B19: RC02 | C19: CCP2 | D19: Personal acreditado realiza trabajos en altura | E19: Asegurar que toda persona que realiza trabajos en altura cuenta con formación teórico / práctica aprobada, evaluación médica vigente y autorización formal, mediante credencial, para desempeñar tareas específicas en altura física. | F19: Curso teórico - práctico en trabajos en altura | G19: Semestral | H19: Documento de aprobación de cursos para trabajadores y supervisores (con foco en inspección), que considere a lo menos: -SPDC: tipos de sistemas, uso, inspección, almacenamiento y líneas de vida. -Entrenamiento práctico: en torre, incluye ascenso/descenso, uso de sistemas, técnicas de posicionamiento, auto rescate y anti-trauma. | I19: N/A
F20: Evaluación médica vigente y compatible | G20: Mensual | H20: Examen médico conforme al “Acuerdo de Homologación de Evaluación de Salud para trabajos en altura física”, emitido por una entidad reconocida. Resultado “Apto”. | I20: N/A
F21: Credencial interna vigente | G21: Mensual | H21: Credencial entregada previa verificación de cumplimiento de requisitos de capacitación y médico. | I21: N/A
F22: Registro consolidado del personal autorizado | G22: Semestral | H22: Base de datos actualizada con trazabilidad del cumplimiento de los requisitos (capacitación, salud, autorización) para cada trabajador. | I22: N/A
F23: Licencia y autorización para operadores de plataformas móviles | G23: Mensual | H23: Para operar plataformas móviles elevadoras, se requiere Licencia Municipal y Autorización Interna específica para el equipo. | I23: N/A
F24: Instrucción en procedimiento de trabajo en altura | G24: Semestral | H24: Instrucción en permiso y procedimiento de trabajo en altura física específico, el que debe incorporar como mínimo los siguientes aspectos: -Uso del SPDC y sus puntos de anclaje. -Uso de plataformas fijas o móviles. -Uso de herramientas en altura. -Respuesta ante emergencia en suspensión. | I24: N/A
B25: RC02 | C25: CCM1 | D25: Uso Correcto de SPDC | E25: Asegurar el uso permanente y correcto (ajuste, conexión) del Sistema Personal para Detención de Caídas (SPDC) certificado e inspeccionado, cada vez que exista exposición a caída desde altura mayor a 1,8 metros. | F25: Certificación del SPDC y sus componentes | G25: Semestral | H25: Todo SPDC (arnés, estrobo, absorbedor, conectores) debe estar certificado por norma chilena o internacional (ej: NCh 1258, ANSI, CE), y registrado como equipo aprobado. | I25: N/A
F26: Inspección periódica por personal autorizado | G26: Mensual | H26: Revisión visual pre-uso por parte del trabajador. Revisión semestral, realizada por un inspector de equipos SPDC, conforme a un programa formal. La frecuencia deberá ajustarse según las condiciones ambientales a las que esté expuesto el equipo. Toda inspección debe quedar registrada en la ficha del equipo. | I26: N/A
F27: Adecuación del SPDC a la tarea | G27: Cada vez | H27: El SPDC debe estar compuesto por elementos compatibles con la tarea y la distancia de caída, incluyendo absorbedores: Tipo 1: Sistema de detención de caídas, incluye absorbedor de energía. Tipo 2: Sistema de sujeción o restricción de desplazamiento, sin absorbedor, evita la caída libre. Sistemas autorretráctiles (SRL) según su clase ANSI: Clase 1 para anclaje sobre el anillo D y Clase 2 a nivel o bajo el anillo D. Todos los componentes deben estar certificados, compatibles y declarados según la tarea. | I27: N/A
F28: Uso correcto del arnés y conexión segura | G28: Cada vez | H28: El arnés debe estar correctamente ajustado y el conector debe estar anclado a un punto seguro (certificado o conforme al diseño original). La organización debe contar con un procedimiento/instructivo que regule esta materia. | I28: N/A
F29: Control del vencimiento del equipo | G29: Mensual | H29: Registro actualizado con fechas de ingreso, vencimiento y baja del SPDC. No se permite uso de equipos vencidos o dañados. | I29: N/A
B30: RC02 | C30: CCM2 | D30: Conexión a Punto Anclaje Certificado | E30: Asegurar que el SPDC esté conectado exclusivamente a un punto de anclaje o sistema de línea de vida que cumpla con certificación vigente, diseño profesional, inspección registrada, identificación visible y capacidad de resistir las cargas de detención de caída según norma. | F30: Certificación y validación de puntos de anclaje | G30: Semestral | H30: Cada punto de anclaje debe estar certificado de fábrica y su instalación debe ser validada por un profesional competente (estructural/calculista) | I30: N/A
F31: Diseño por profesional competente (estructural) | G31: Trimestral | H31: Puntos de anclaje fijos o sistemas de línea de vida deben contar con memoria de cálculo o plano emitido por profesional competente. Toda línea de vida, temporal o permanente, debe estar certificada. No se permiten líneas de vida fabricadas en terreno con prensas tipo candado, aunque cuenten con cálculo estructural. | I31: N/A
F32: Inspección documentada y periódica | G32: Trimestral | H32: Debe existir un programa formal de inspección visual y técnica, con registros físicos o digitales asociados a cada punto de anclaje. | I32: N/A
F33: Identificación clara en terreno | G33: Mensual | H33: Todo punto de anclaje certificado, debe estar identificado en terreno con su resistencia, vigencia y número. No aplica a partes estructurales genéricas como rosetas, salvo que hayan sido certificados expresamente como puntos de anclaje. | I33: N/A
F34: Sistema de control de vigencia y mantenimiento | G34: Trimestral | H34: Registro actualizado del estado de cada punto de anclaje, con fecha de última inspección, próxima revisión y responsable. | I34: N/A
F35: Instrucción al personal sobre puntos de conexión seguros | G35: Anual | H35: Todo trabajador debe estar instruido para identificar visualmente un punto de anclaje seguro y distinguir estructuras no aptas en el área de trabajo. | I35: N/A
B36: RC02 | C36: CCM3 | D36: Capacidad de Rescate en Suspensión | E36: Asegurar que exista un plan específico y operativo de rescate en suspensión, con equipos adecuados, disponibles e inspeccionados en el lugar de trabajo, y con personal entrenado para ejecutar la maniobra en el menor tiempo posible, evitando consecuencias fatales por trauma por suspensión. | F36: Plan de rescate documentado y específico | G36: Semestral | H36: Documento formal asociado a cada tarea en altura que contemple procedimiento, roles, medios y tiempo de respuesta. Debe estar disponible y conocido por el equipo. | I36: N/A
F37: Equipamiento de rescate disponible e inspeccionado | G37: Semestral | H37: Equipos y medios necesarios para rescatar a un trabajador en suspensión deben estar disponibles en el lugar de trabajo, conforme al procedimiento de emergencia aplicable a la tarea. | I37: N/A
F38: Personal entrenado para ejecutar rescates | G38: Semestral | H38: El equipo de trabajo o apoyo debe haber recibido entrenamiento teórico y práctico (incluye uso de sistema anti-trauma). El registro de esto debe estar disponible. | I38: N/A
F39: Simulacros y validación de tiempos de respuesta | G39: Trimestral | H39: Se deben realizar ejercicios que validen el tiempo máximo aceptable de rescate tras una caída con suspensión. Registros deben quedar disponibles. | I39: N/A
F40: Difusión y comunicación del plan de rescate | G40: Trimestral | H40: El plan debe ser comunicado de forma verbal o escrita al equipo antes del inicio de las tareas en altura. | I40: N/A
B42: RIESGO FATALIDAD | C42: CONTROL | D42: NOMBRE DEL CONTROL | E42: REQUISITO | G42: EVIDENCIA | I42: CUMPLIMIENTO | J42: OBSERVACIONES | K42: FECHA IMPLEMENTACIÓN | L42: PLAN MITIGADOR
B43: RC02 | C43: CP1 | D43: Gestión del cambio para modificaciones que afecten trabajos en altura | E43: Toda modificación en el diseño de procesos, tareas o equipos que impliquen cambios en condiciones de trabajo en altura debe ser gestionada a través del sistema de gestión del cambio (GdC). | G43: a. El supervisor(a) debe identificar cambios que afecten seguridad o introduzcan nuevas interacciones no previstas (ej. sustitución de equipos, acceso a nuevas zonas, reubicación de plataformas). | I43: N/A
G44: b. Se debe elaborar un análisis de riesgo específico y documentado antes de implementar cualquier modificación. | I44: N/A
G45: c. Ningún trabajador(a) podrá intervenir estructuras o procesos modificados sin que se haya cerrado formalmente la gestión del cambio. | I45: N/A
B46: RC02 | C46: CP2 | D46: Áreas de tránsito y desplazamiento libres y despejadas | E46: Las zonas de tránsito asociadas a trabajos en altura deben mantenerse libres de obstáculos, materiales, herramientas o residuos que dificulten el desplazamiento seguro del personal. | G46: a. El supervisor(a) debe verificar que los pasillos, accesos a plataformas y escaleras se encuentren habilitados y sin interferencias antes de iniciar tareas. | I46: N/A
G47: b. Se debe implementar una rutina de limpieza y despeje al término de cada jornada o turno de trabajo en altura. | I47: N/A
...

Sheet RF03
B2: GERENCIA DE SEGURIDAD Y SALUD OCUPACIONAL - CHUQUICAMATA
B4: LISTADO DE AUTODIAGNÓSTICO RIESGO DE FATALIDAD N°03: MANIOBRAS DE IZAJE
B6: ELEMENTOS DEL CONTROL | I6: CUMPLIMIENTO GENERAL
I7: =AVERAGEIF(I14:I77,"<>N/A") -> 0
B10: Alcance | C10: El escenario de este riesgo de fatalidad incluye: • Actividades con cargas elevadas por medios mecánicos que incluyen grúas fijas (puente grúa) o móviles (grúas articuladas, grúas telescópicas, grúas de celosía y camión pluma). • Cargas en movimiento, incluido el transporte, elevaciones que involucran múltiples grúas, transferencia de cargas a otras y colapso de grúas. • Operaciones con herramientas manuales de levante (tecle de cadena o palanca, entre otros). • Operaciones de levante con grúa torre. • Operaciones con equipo extiende tubos (sidebooms).
B11: Exclusión | C11: Este evento considera como exclusión los siguientes escenarios: • Operaciones con manipulador de neumáticos. • Operaciones con porta contenedores. • Uso de elevadores en plantas. • Operaciones de levante con grúas horquillas.
B13: RIESGO FATALIDAD | C13: CONTROL CRÍTICO | D13: NOMBRE DEL CONTROL CRÍTICO | E13: OBJETIVO | F13: REQUISITO | G13: MONITOREO | H13: EVIDENCIA | I13: CUMPLIMIENTO | J13: OBSERVACIONES | K13: FECHA IMPLEMENTACIÓN | L13: PLAN MITIGADOR
B14: RC03 | C14: CCP1 | D14: Equipos y elementos de izaje conforme a especificaciones técnicas | E14: Prevenir la falla catastrófica de equipos y elementos de izaje, garantizando que su integridad estructural y funcional se mantiene conforme al diseño del fabricante, a través de un programa de inspección, mantenimiento y certificación. | F14: Plan de Mantenimiento Vigente y Ejecutado. | G14: Trimestral | H14: Solicitar la pauta de mantenimiento del fabricante y los registros de las últimas mantenciones preventivas ejecutadas. | I14: 0
F15: Certificación del Equipo | G15: Anual | H15: Solicitar el certificado del equipo al proveedor, fabricante o representante de la marca. | I15: N/A
F16: Inspección de Pre-uso Diaria Realizada. | G16: Cada vez | H16: Solicitar el checklist de pre-uso del equipo del turno actual, verificando que esté completo y firmado por el operador. | I16: N/A
F17: Integridad y Certificación de Elementos de Izaje. | G17: Semestral | H17: Solicitar que los aparejos (eslingas, grilletes, otros) cuenten con certificación correspondiente. | I17: N/A
F18: Sistemas de Seguridad del Equipo Operativos. | G18: Trimestral | H18: Solicitar registros de pruebas funcionales del sistema limitador de momento de carga (LMI), frenos y paradas de emergencia. | I18: N/A
F19: Personal de Mantenimiento Capacitado | G19: Anual | H19: Solicitar los registros de capacitación del personal (mecánico / eléctrico) en el equipo específico. | I19: N/A
F20: Gestión de Reparaciones Críticas. | G20: Semestral | H20: Toda intervención estructural requiere un procedimiento de reparación y validación de ingeniería documentada. En equipos antiguos o sin información técnica disponible, el área a cargo deberá identificar los componentes críticos y asegurar su integridad. | I20: N/A
B21: RC03 | C21: CCP2 | D21: Estabilizadores operativos y posicionamiento seguro de equipos de izaje | E21: Asegurar que los equipos de izaje móviles posicionen sobre una superficie estable y nivelada, de acuerdo con las especificaciones del fabricante y un análisis del terreno, para prevenir eventuales inestabilidades del equipo durante la maniobra. | F21: Evaluación de Terreno | G21: Cada vez | H21: Solicitar el análisis o protocolo de evaluación de terreno. | I21: N/A
F22: Estabilizadores Completamente Extendidos. | G22: Cada vez | H22: Verificar en terreno que los estabilizadores y sus bases de apoyo (almohadillas) están desplegados al 100% según manual. | I22: N/A
F23: Nivelación del Equipo Verificada. | G23: Cada vez | H23: Verificar visualmente el indicador de nivel(burbuja) del equipo, asegurando que se encuentra dentro de los parámetros de | I23: N/A
F24: Tabla de Carga Visible y Conocida. | G24: Cada vez | H24: Confirmar que la tabla de carga del equipo es visible y legible para el operador y corresponde a la configuración del izaje. | I24: N/A
F25: Condiciones de Viento Controladas. | G25: Cada vez | H25: Solicitar registros de medición de velocidad de viento y verificar que se encuentran dentro de los límites permitidos para la maniobra, según tabla de factores de viento del equipo de izaje. | I25: N/A
F26: Inspección de Sistemas de Estabilidad. | G26: Cada vez | H26: Solicitar checklist de pre-uso que incluya la revisión de neumáticos, sistema de suspensión y sistemas hidráulicos de estabilización. | I26: N/A
F27: Señalización de Barras Estabilizadoras | G27: Semestral | H27: Las barras estabilizadoras del equipo de izaje, deben estar señalizadas con elementos reflectantes, que indiquen sus distintas. | I27: N/A
B28: RC03 | C28: CCP3 | D28: Personal acreditado para maniobras de izaje | E28: Asegurar que toda persona que participe en una maniobra de izaje (operador, rigger, personal de apoyo) posea las competencias técnicas y capacitaciones requeridas, y se encuentre en condiciones físicas y psicológicas adecuadas, para garantizar una ejecución segura y precisa de la tarea. | F28: Acreditación Vigente de Operador y rigger. | G28: Trimestral | H28: Revisar si está operativo y actualizado el sistema que registra las licencias de cada operador y rigger. En terreno solicitar que el operador y riggger porten su licencia, la que debe ser adecuada al equipo y tonelaje. | I28: N/A
F29: Exámenes Psicosensotécnico Vigente. | G29: Anual | H29: Solicitar respaldo de que los exámenes psico- sensotécnicos rigurosos del personal que opera se encuentran vigentes y aprobados, conforme al Acuerdo de Homologación de Salud. | I29: N/A
F30: Evaluación Médica de Aptitud. | G30: Anual | H30: Verificar en el sistema que el personal cuenta con un examen de salud compatible y sin restricciones para el cargo. | I30: N/A
F31: Competencias y Capacitación | G31: Anual | H31: -Solicitar registros de aprobación de curso del riesgo de fatalidad para toda persona que participa en la actividad. -Los operadores deben disponer de la aprobación de un curso teórico y práctico, realizado por OTEC o fabricante/representante de la marca, en la operación del tipo de equipo de izaje de carga (grúas móviles, camiones pluma, puentes grúa, monorrieles, tecles u otros). Se debe considerar evaluación teorica y práctica sobre operación y conocimiento de los sistemas del equipo en marca y modelo, realizada por organismo certificador validado por Chile Valora o fabricante/representantes de la marca. Todo operador de equipos de izaje del tipo móvil, debe contar con Licencia Municipal vigente. -Los Rigger deben cumplir con la aprobación de una capacitación teórico / práctica, realizada por una OTEC. Se debe considerar la certificación o evaluación de sus competencias, según el límite de carga (nivel A, B o C) de la tarea, por un centro acreditado por Chilevalora. | I31: N/A
B32: RC03 | C32: CCP4 | D32: Comunicación bidireccional efectiva entre operador y rigger | E32: Asegurar una comunicación clara, continua y sin ambigüedades entre el rigger y el operador durante toda la maniobra de izaje, utilizando un sistema de comunicación bidireccional radial, para garantizar que cada movimiento sea ejecutado de forma coordinada y segura. | F32: Protocolo de Comunicación para Izaje. | G32: Anual | H32: Solicitar el procedimiento que estandariza las comunicaciones y señales de mano para maniobras de izaje. | I32: N/A
F33: Canal de Radio de Uso Exclusivo. | G33: Por evento | H33: Verificar en el plan de izaje o procedimiento que se ha asignado un canal de radio de uso exclusivo para la maniobra. | I33: N/A
F34: Equipos de Radio Operativos. | G34: Diario | H34: Verificar en terreno que el operador y rigger cuentan con equipos de radio y que estos han sido inspeccionados (batería, funcionalidad). | I34: N/A
F35: Prueba de Comunicación Pre-Izaje. | G35: Diario | H35: Consultar al operador y rigger si realizaron la prueba de comunicación antes de iniciar la maniobra y cómo la documentaron (ej. en ART). | I35: N/A
F36: Señales de Mano Estandarizadas. | G36: Mensual | H36: Verificar que en el área de izaje se encuentre visible la infografía con las señales de mano estandarizadas. | I36: N/A
F37: Protocolo ante Pérdida de Comunicación | G37: Anual | H37: Verificar que el procedimiento de izaje incluye la obligatoriedad de detener toda maniobra ante la pérdida de comunicación. | I37: N/A
B38: RC03 | C38: CCP5 | D38: Plan de Izaje | E38: Asegurar que toda maniobra de izaje sea planificada, coordinada y ejecutada bajo condiciones controladas, considerando la capacidad técnica del equipo, la estabilidad del terreno, las características y centro de gravedad de la carga, las condiciones ambientales y la competencia del personal, garantizando además la integridad y estabilidad de la carga en su disposición final. | F38: Clasificación de Izaje (*Crítico o No Crítico) | G38: Cada vez | H38: Se debe definir si la maniobra de izaje será crítica o no. En caso de ser crítico el Plan debe ser revisado y autorizado por personal especialista de operaciones, mantención, servicios o proyectos de Codelco, independiente de si la tarea es realizada por personal propio o empresa contratista. | I38: N/A
F39: Requisitos y Autorización del Plan de Izaje | H39: El plan de Izaje debe contar al menos con: -Nombre del especialista. -Especificaciones técnicas para asegurar medidas de control para la estabilidad de terreno. -Ángulo de inclinación seguro del equipo respecto al plano de terreno. -Calculo de estabilidad del suelo. (para equipos de mayor tonelaje) -Requerimientos y exigencias para maniobras de izaje críticos y no críticos. -Layout o esquema para las maniobras de izaje críticas. -Tipo de cálculo. -Peso de la carga -Ubicación del centro de gravedad (dentro o fuera del cuerpo del elemento). -Punto de Izaje, entre otros. | I39: N/A
F40: Certificación de Equipos y Elementos de Izaje | G40: Semestral | H40: Solicitar los certificados vigentes de los equipos de izaje (grúas) y de todos los accesorios (eslingas, grilletes, etc.). Verificar en terreno que los elementos físicos coincidan con lo certificado y tengan su inspección del período vigente. | I40: N/A
F41: Análisis de Entorno y Estabilidad del Terreno | G41: Cada vez | H41: Solicitar el registro de evaluación de la superficie de operación. (Para izajes críticos, verificar que el plan esté respaldado por un informe de mecánica de suelos que valide la estabilidad del terreno). | I41: N/A
F42: Análisis y Validación de Punto de Descarga Final | G42: Cada vez | H42: Verificar que el plan de izaje incluye un análisis explícito de la estructura o superficie donde se depositará la carga, respaldado por una memoria de cálculo o validación de ingeniería que garantice su capacidad para soportar el peso. | I42: N/A
F43: Coordinación y Comunicación Previa a la Maniobra | G43: Cada vez | H43: Solicitar el registro de la reunión de coordinación (ej. en ART), donde se demuestre que el plan de izaje completo, incluyendo riesgos, controles y protocolo de comunicación, fue difundido y comprendido por todo el equipo de trabajo antes de iniciar. | I43: N/A
B44: RC03 | C44: CCM1 | D44: Segregación y control de acceso en área de maniobras | E44: Evitar la exposición de personas a la línea de fuego de una maniobra de izaje (caída de carga, volcamiento de equipo, golpe de látigo), asegurando que el área de peligro sea físicamente segregada y el acceso controlado antes, durante y después de la operación. | F44: Plan de Segregación en Plan de Izaje. | G44: Cada vez | H44: Solicitar el plan de izaje y verificar que incluye un diagrama o esquema que define el radio y tipo de segregación requerida. | I44: N/A
F45: Delimitación de Área de Exposición a Cargas Suspendidas | G45: Cada vez | H45: Verificar en terreno que la segregación está implementada con barreras físicas (ej. barreras de concreto, conos con cadena). | I45: N/A
F46: Señalización de Peligro Clara y Visible. | G46: Cada vez | H46: Verificar en terreno la existencia de letreros de advertencia claros ("Peligro: Izaje de Cargas", "No Pasar") en todos los accesos. | I46: N/A
...

Sheet RF04
B2: GERENCIA DE SEGURIDAD Y SALUD OCUPACIONAL - CHUQUICAMATA
B4: LISTADO DE AUTODIAGNÓSTICO RIESGO DE FATALIDAD N°04: LIBERACIÓN DESCONTROLADA DE ENERGÍAS
B6: ELEMENTOS DEL CONTROL | I6: CUMPLIMIENTO GENERAL
I7: =AVERAGEIF(I14:I62,"<>N/A") -> 0
B10: Alcance | C10: Su alcance comprende actividades tales como: Construcción, instalación, montaje, intervención, ajustes, inspección, mantención, reparación, pruebas, puesta en marcha, operación y modificaciones en herramientas, equipos, maquinaria, instalaciones y sistemas con presencia de estas energías. Este riesgo aplica a todas aquellas energías que pudieran provocar un accidente grave o fatal, tales como: • Potencial • Mecánica • Neumática • Hidráulica • Entre otras.
B11: Exclusión | C11: Se excluyen de este Riesgo las siguientes energías: • Energía Eléctrica • Energía Cinética de Vehículos y Equipos • Energía Química • Energía Calórica • Interacción Mecánica / Atrapamientos • Tiro y Arrastre • Explosivos • Caída de Objetos y Personas • Sistemas de Baja Energía (que no representen riesgo de accidentes graves y/o fatales)
B13: RIESGO FATALIDAD | C13: CONTROL CRÍTICO | D13: NOMBRE DEL CONTROL CRÍTICO | E13: OBJETIVO | F13: REQUISITO | G13: MONITOREO | H13: EVIDENCIA | I13: CUMPLIMIENTO | J13: OBSERVACIONES | K13: FECHA IMPLEMENTACIÓN | L13: PLAN MITIGADOR
B14: RC04 | C14: CCP1 | D14: Identificación, aislación, bloqueo y verificación de energía cero | E14: Garantizar que toda intervención en equipos y sistemas se ejecute bajo una condición verificada de energía cero, asegurando la identificación, aislación, bloqueo y control de energias residuales para eliminar la liberación descontrolada de energía. | F14: Procedimiento de Aislación y Bloqueo Vigente. | G14: Anual | H14: Solicitar el procedimiento de bloqueo para sistemas de alta presión y verificar su última fecha de revisión y su difusión. | I14: 0
F15: Información Técnica y Diagramas Actualizados. | G15: Semestral | H15: Solicitar o planos/manuales técnicos (mecánica/potencial) y verificar en terreno que los puntos de bloqueo y liberación de energía residual coinciden con la realidad. Semestral | I15: N/A
F16: Personal Capacitado para Aislación y Bloqueo. | G16: Anual | H16: Solicitar competencias según perfil o descriptor de cargo y los registros de aprobación de capacitaciones para el personal que ejecuta tareas de aislación y bloqueo. | I16: N/A
F17: Dispositivos de Bloqueo Estandarizados. | G17: Trimestral | H17: Verificar en pañol y en terreno que los dispositivos de bloqueo (ej. bloqueadores de válvula) son los estandarizados y están en buen estado. | I17: N/A
F18: Verificación de Energía Cero en terreno. | G18: Semestral | H18: Solicitar el procedimiento y verificar en terreno que se ejecuta la medición o comprobación de ausencia de energía antes de intervenir el equipo. | I18: N/A
F19: Registros de Bloqueo y Permisos de Trabajo. | G19: Mensual | H19: Solicitar los permisos de trabajo y las tarjetas de bloqueo de una intervención reciente y verificar su correcto llenado y autorización. | I19: N/A
B20: RC04 | C20: CCP2 | D20: Sistemas y elementos de contención de energía | E20: Garantizar que todo componente crítico de contención o retención de energía opere bajo sus especificaciones originales de diseño, asegurando su reemplazo oportuno ante el cumplimiento de su vida útil definida o cualquier evidencia de deterioro en su condición, para evitar fallas catastróficas. | F20: Certificación y Especificación de Componentes. | G20: Anual | H20: Verificar que los componentes críticos (mangueras, cables, frenos, acumuladores) instalados corresponden a las especificaciones originales del fabricante y cuentan con su certificación de calidad/origen. | I20: N/A
F21: Plan de Mantenimiento e Inspección. | G21: Mensual | H21: Solicitar el programa de mantenimiento y verificar los registros de inspección de los sistemas de energía, asegurando la detección de fatiga, desgaste o fugas. | I21: N/A
F22: Criterios de Reemplazo (Vida Útil o Condición). | G22: Trimestral | H22: Solicitar la pauta técnica que define el momento de cambio (por fecha de vencimiento/horas o por criterio de rechazo técnico/condición) y verificar su cumplimiento. | I22: N/A
F23: Disponibilidad de Repuestos Críticos. | G23: Semestral | H23: Verificar la disponibilidad de stock o componentes de recambio para elementos de seguridad, asegurando la continuidad operacional sin improvisaciones. | I23: N/A
F24: Competencias del Mantenedor. | G24: Anual | H24: Solicitar registros que definan y respalden las competencias del personal que inspecciona y reemplaza componentes críticos. | I24: N/A
F25: Prohibición de Reparaciones Improvisadas. | G25: Mensual | H25: Verificar en terreno la ausencia de reparaciones no estandarizadas ("parches", soldaduras hechizas, nudos) en elementos sometidos a presión o tensión. | I25: N/A
B26: RC04 | C26: CCP3 | D26: Dispositivos de protección y alivio de presión | E26: Garantizar la operatividad y vigencia de todos los dispositivos diseñados para limitar, aliviar o contener la energía crítica (válvulas de seguridad, limitadores de carrera, frenos de emergencia, celdas de carga), asegurando que se mantengan calibrados y protegidos contra intervenciones no autorizadas. | F26: Inventario de Dispositivos de Protección. | G26: Anual | H26: Solicitar el inventario completo de dispositivos de protección de presión (válvulas de alivio, etc.) por equipo. | I26: N/A
F27: Programa de Calibración y Certificación. | G27: Semestral | H27: Solicitar el programa de mantenimiento y los certificados de calibración vigentes para las válvulas de alivio. | I27: N/A
F28: Inspección de Instrumentos de Medición. | G28: Mensual | H28: Solicitar los registros de inspección de pre-uso y mantenimiento que verifiquen el buen estado de los manómetros. | I28: N/A
F29: Sellos de Seguridad Intactos. | G29: Trimestral | H29: Verificar en terreno que los dispositivos de protección de presión cuentan con sus sellos de seguridad o precintos intactos. | I29: N/A
F30: Prohibición de Modificación no Autorizada. | G30: Anual | H30: Solicitar el procedimiento que prohíbe y sanciona la adulteración de los dispositivos de seguridad de los equipos. | I30: N/A
F31: Gestión de Fallas y Reparaciones. | G31: Por evento | H31: Solicitar los registros de mantenimiento correctivo y verificar que las reparaciones de estos dispositivos se realizan por personal capacitado. | I31: N/A
B32: RC04 | C32: CCM1 | D32: Segregación y control de acceso | E32: Impedir la exposición de personas a la línea de fuego durante pruebas de presión o en zonas con riesgo de falla de componentes hidráulicos/neumáticos, asegurando que el área de peligro sea físicamente segregada y el acceso estrictamente controlado. | F32: Procedimiento de Segregación para Pruebas. | G32: Anual | H32: Solicitar el procedimiento que define el tipo de barrera y el cálculo del radio de exclusión para pruebas de presión. | I32: N/A
F33: Implementación de Barreras Físicas (Duras). | G33: Por evento | H33: Verificar en terreno que el área de la prueba está aislada con barreras físicas efectivas (ej. biombos, barreras de concreto). | I33: N/A
F34: Señalización de Peligro Clara y Visible. | G34: Por evento | H34: Verificar en terreno la existencia de letreros de advertencia claros ("Peligro: Prueba Hidráulica", "No Pasar") en todos los accesos. | I34: N/A
F35: Control de Puntos de Acceso. | G35: Por evento | H35: Verificar que los puntos de acceso a la zona segregada están controlados, ya sea por barreras o por personal designado (vigía). | I35: N/A
F36: Comunicación Radial Previa. | G36: Por evento | H36: Solicitar el registro o consultar al supervisor si se realizó la comunicación radial a todas las áreas antes de iniciar la presurización. | I36: N/A
F37: Verificación al Cumplimiento de Segregación. | G37: Trimestral | H37: Solicitar los informes de verificaciones o inspecciones al cumplimiento de la segregación en terreno. | I37: N/A
B38: RC04 | C38: CCM2 | D38: Capacidad de respuesta ante emergencia | E38: Garantizar una respuesta sistémica, inmediata y eficaz tras una liberación descontrolada de energías, integrando la comunicación, la brigada y la atención médica, para rescatar y atender a las personas afectadas en el menor tiempo posible. | F38: Plan de Emergencia Específico Vigente. | G38: Anual | H38: Solicitar el plan de emergencia y verificar su instrucción a los trabajadores. | I38: N/A
F39: Brigada y Personal Médico Entrenados. | G39: Semestral | H39: Solicitar los registros de entrenamiento de la brigada y del personal de salud en manejo de lesiones por liberación descontrolada de energías. | I39: N/A
F40: Sistemas de Comunicación de Emergencia Funcionales. | G40: Trimestral | H40: Solicitar registros de pruebas funcionales de los sistemas de comunicación y de los canales de emergencia. | I40: N/A
F41: Simulacros Específicos Realizados y Evaluados. | G41: Semestral | H41: Solicitar el informe del último simulacro de liberación de liberación descontrolada de energía, verificando tiempos de respuesta y planes de acción. | I41: N/A
F42: Personal Capacitado en Respuesta Inicial. | G42: Trimestral | H42: Verificar en terreno, mediante entrevistas, que el personal conoce el protocolo de aviso y las acciones de primera respuesta. | I42: N/A
B44: RIESGO FATALIDAD | C44: CONTROL | D44: NOMBRE DEL CONTROL | E44: REQUISITO | G44: EVIDENCIA | I44: CUMPLIMIENTO | J44: OBSERVACIONES | K44: FECHA IMPLEMENTACIÓN | L44: PLAN MITIGADOR
B45: RC04 | C45: CP1 | D45: Mapa actualizado de líneas y sistemas presurizados | E45: Todas las áreas operativas deben contar con diagramas o planos (P&ID) actualizados y disponibles, que identifiquen la totalidad de los sistemas, líneas y equipos que operan con energía hidráulica o neumática a presiones mayores o iguales a 6 bares. | G45: a. El supervisor del área es responsable de asegurar que los diagramas de sus sistemas presurizados se encuentren en su última versión, reflejando fielmente la instalación en terreno, incluyendo todas las modificaciones. | I45: N/A
G46: b. Antes de planificar cualquier intervención, el supervisor y el personal ejecutor deben consultar los diagramas para identificar correctamente las líneas, los puntos de aislación, las válvulas de venteo y otras fuentes de energía. | I46: N/A
G47: c. Los diagramas deben estar disponibles en formato físico o digital en puntos de consulta accesibles para todo el personal del área, como salas de control, oficinas de supervisión o pañoles de mantenimiento. | I47: N/A
...

Sheet RF05
B2: GERENCIA DE SEGURIDAD Y SALUD OCUPACIONAL - CHUQUICAMATA
B4: LISTADO DE AUTODIAGNÓSTICO RIESGO DE FATALIDAD N°05: CAÍDA DE ROCAS EN MINA RAJO
B6: ELEMENTOS DEL CONTROL | I6: CUMPLIMIENTO GENERAL
I7: =AVERAGEIF(I14:I44,"<>N/A") -> 0
B10: Alcance | C10: Caída de rocas individual o masiva en áreas operativas de minería a cielo abierto, que puede resultar en lesiones graves y/o fatales por aplastamiento o impacto a las personas. Escenarios definidos son: • Carguío de mineral en la frente. • Descarga de mineral en stock. • Carguío de estéril. • Descarga de estéril en botaderos. • Limpieza de taludes. • Limpieza o saneamiento de bancos.
B11: Exclusión | C11: Este evento considera como exclusión los siguientes escenarios. • Deslizamiento de rocas en pilas. • Excavaciones para construcción (proyectos). • Tronaduras de producción y cierre. (Fly rock) • Tronadura secundaria.(Fly rock) • Tronaduras civiles (Fly rock) (proyectos) • Inestabilidades a nivel de banco, inter-rampa y talud global. • Caída de rocas desde CAEX durante el transporte de material.
B13: RIESGO FATALIDAD | C13: CONTROL CRÍTICO | D13: NOMBRE DEL CONTROL CRÍTICO | E13: OBJETIVO | F13: REQUISITO | G13: MONITOREO | H13: EVIDENCIA | I13: CUMPLIMIENTO | J13: OBSERVACIONES | K13: FECHA IMPLEMENTACIÓN | L13: PLAN MITIGADOR
B14: RF05 | C14: CCP1 | D14: MODELO Y MONITOREO GEOTÉCNICO DE ESTABILIDAD DE TALUDES Y BANCOS | E14: Anticipar y controlar la inestabilidad de taludes y bancos, asegurando que el diseño minero se base en un modelo geotécnico válido y que la monitoreo continua de las zonas de riesgo permita tomar decisiones operacionales oportunas para prevenir la caída de rocas | F14: Captura Sistemática y Actualización de Modelos. | G14: Trimestral | H14: Solicitar el modelo geotécnico y verificar el registro de sus últimas actualizaciones con data de mapeo y sondajes. | I14: 0
F15: Bases Geotécnicas para Diseño Vigentes. | G15: Anual | H15: Solicitar el informe de bases geotécnicas para el diseño actual del rajo, verificando el cumplimiento de los criterios de aceptabilidad. | I15: N/A
F16: Mapa de RiesgoGeotécnico Actualizado y Difundido | G16: Diario | H16: Solicitar el mapa de riesgos geotécnicos del turno y verificar su actualización y los registros de difusión al personal. | I16: N/A
F17: Monitoreo Continuo Geotécnico | G17: Semanal | H17: Solicitar reportes de disponibilidad del monitoreo geotécnico y verificar en la sala de control que están en línea y vigilando zonas críticas. | I17: N/A
F18: Gestión de Alertas de Monitoreo. | G18: Diario | H18: Solicitar el protocolo de gestión de alertas y los registros de las últimas alertas, verificando su correcta gestión. | I18: N/A
F19: Evaluación Geométrica (Sistema Full Control). | G19: Mensual | H19: Solicitar los reportes del sistema de evaluación de talud (Full Control) para verificar la conciliación geométrica de los bancos | I19: N/A
F20: Personal Especialista Competente. | G20: Anual | H20: Solicitar el listado de competencias según perfil o descriptor del cargo y documentos que respalden su cumplimiento, para el personal que interpreta los datos geotécnicos y toma decisiones 24/7. | I20: N/A
B21: RF05 | C21: CCP2 | D21: SANEAMIENTO Y LIMPIEZA DE BERMAS Y TALUDES | E21: Mantener los bancos y taludes en condiciones de diseño, asegurando que el saneamiento y limpieza sistemática eliminen el material suelto o colgado para prevenir la caída de rocas | F21: Plan de Saneamiento Sistemático. | G21: Mensual | H21: Solicitar el programa de saneamiento de taludes y los registros que demuestren su cumplimiento | I21: N/A
F22: ProcedimientoOperacional de Saneamiento | G22: Trimestral | H22: Solicitar el procedimiento de trabajo seguro para saneamiento y verificar su aplicación en terreno | I22: N/A
F23: Personal Capacitado para Saneamiento. | G23: Anual | H23: Solicitar registros de curso del riesgo de fatalidad e instrucción del procedimiento de saneamiento y respaldos de la experiencia del personal y supervisores a cargo | I23: N/A
F24: Uso de Equipos Adecuados. | G24: Semanal | H24: Verificar en terreno que los equipos utilizados para el saneamiento son los definidos en el estándar para esa tarea. | I24: N/A
F25: Inspección Geotécnica Post-Saneamiento | G25: Por Evento | H25: Solicitar el informe o registro de la inspección geotécnica que valida la efectividad del saneamiento realizado | I25: N/A
F26: Protocolo de Recepción Conforme de Área | G26: Trimestral | H26: Solicitar el registro de "recepción conforme"del área saneada, firmado por la supervisión antes de reanudar las operaciones. | I26: N/A
B27: RF05 | C27: CCP3 | D27: CONTROL TOPOGRÁFICO Y DRENAJE | E27: Controlar la geometría de las frentes de carguío y gestionar los afloramientos de agua, para prevenir la formación de material colgado y la inestabilidad del talud inducida por la presencia de agua | F27: Estándar de Altura de Frente de Carguío. | G27: Anual | H27: Solicitar el estándar que define la altura máxima de la frente de carguío según el tipo de equipo y material. | I27: N/A
F28: Monitoreo Topográfico de Frentes | G28: Semanal | H28: Solicitar informes de medición topográfica que verifiquen el cumplimiento de la altura y geometría de las frentes de carguío | I28: N/A
F29: Procedimiento de Rebaje de Altura. | G29: Por Evento | H29: Solicitar el procedimiento para rebajar frentes fuera de estándar y los registros de su ejecución. | I29: N/A
F30: Mapa de Afloramientos de Agua. | G30: Mensual | H30: Solicitar el mapa que identifica los puntos de afloramiento de agua en bancos y verificar su actualización | I30: N/A
F31: Plan de Gestión de Drenajes | G31: Mensual | H31: Solicitar el plan de acción y los registros de ejecución para la canalización o drenaje de los afloramientos identificados. | I31: N/A
F32: Competencias del Personal | G32: Anual | H32: Solicitar y verificar las competencias del perfil o descriptor del cargo del personal que realiza mediciones topográficas y gestión de drenajes. | I32: N/A
B33: RF05 | C33: CCM1 | D33: ISEGREGACIÓN FÍSICA Y CONTENCIÓN ESTRUCTURAL | E33: Contener la caída de rocas y restringir el acceso a zonas de riesgo, mediante la instalación de sistemas de contención (mallas, pretiles) y la implementación de barreras físicas para proteger a las personas y equipos expuestos. | F33: Diseño Geotécnico de Sistemas de Contención | G33: Anual | H33: Solicitar el diseño o estándar técnico para pretiles, mallas u otras barreras, verificando su aprobación por Geotecnia. | I33: N/A
F34: Implementación y Mantención de Contención | G34: Semanal | H34: Solicitar informes de inspección topográfica y visual que verifiquen el cumplimiento de la geometría y estado de los pretiles y mallas. | I34: N/A
F35: Mapa de Zonas de Riesgo Actualizado. | G35: Diario | H35: Solicitar el mapa de riesgo geotécnico del turno y verificar la clara identificación de zonas que requieren segregación | I35: N/A
F36: Implementación de Barreras Físicas (Duras). | G36: Semanal | H36: Verificar en terreno que las zonas de alto riesgo están aisladas con barreras físicas efectivas según estándar. | I36: N/A
F37: Protocolo de Control de Acceso Formal | G37: Trimestral | H37: Solicitar el procedimiento de autorización de ingreso a áreas restringidas y revisar los registros de permisos emitidos | I37: N/A
F38: Verificación alCumplimiento de contención y segregación | G38: Trimestral | H38: Solicitar los informes de inspección que verifiquen el cumplimiento de la contención y segregación en terreno. | I38: N/A
B39: RF05 | C39: CCM2 | D39: CAPACIDAD DE RESPUESTA ANTE EMERGENCIA | E39: Garantizar una respuesta sistémica, inmediata y eficaz tras un deslizamiento o caída de rocas, integrando la alarma, la evacuación, la brigada de rescate y la atención médica, para rescatar y atender a las personas afectadas en el menor tiempo posible. | F39: Plan de Emergencia Específico para Deslizamientos. | G39: Anual | H39: Solicitar el plan de emergencia y verificar su actualización, incluyendo protocolos de alarma, evacuación y rescate. | I39: N/A
F40: Brigada de Rescate Entrenada | G40: Semestral | H40: Solicitar los registros de entrenamiento de los integrantes de la brigada en rescate en taludes. | I40: N/A
F41: Equipamiento de Rescate y Atención Médica Operativo. | G41: Mensual | H41: Solicitar los registros de inspección mensual de los equipos de rescate (ambulancia, equipos y herramientas especializadas). | I41: N/A
F42: Sistema de Alarma yComunicación Funcional. | G42: Trimestral | H42: Solicitar registros de pruebas funcionales de los sistemas de alarma y de los canales de comunicación de emergencia | I42: N/A
F43: Simulacros Específicos Realizados y Evaluados. | G43: Semestral | H43: Solicitar el informe del último simulacro de deslizamiento, verificando tiempos de respuesta y planes de acción de las brechas. | I43: N/A
F44: Personal Capacitado en el Plan de Emergencia. | G44: trimestral | H44: Verificar que el personal ha sido instruido en el plan de emergencia y conoce el protocolo de aviso y las rutas de evacuación. | I44: N/A
B46: RIESGO FATALIDAD | C46: CONTROL | D46: NOMBRE DEL CONTROL | E46: REQUISITO | G46: EVIDENCIA | I46: CUMPLIMIENTO | J46: OBSERVACIONES | K46: FECHA IMPLEMENTACIÓN | L46: PLAN MITIGADOR
B47: RF05 | C47: CP1 | D47: MONITOREO DE SECTORES DETENIDOS / SIN OPERACIÓN | E47: Toda área de la mina que haya estado inactiva o sin operaciones por un período prolongado debe ser formalmente evaluada por personal especialista antes de autorizar el reingreso y el reinicio de los trabajos. | G47: El supervisor del área es responsable deasegurar que los accesos a sectores detenidos se encuentren físicamente bloqueados con pretiles o barreras y debidamente señalizados, prohibiendo el ingreso no autorizado. | I47: N/A
...

Sheet RF06
B2: GERENCIA DE SEGURIDAD Y SALUD OCUPACIONAL - CHUQUICAMATA
B4: LISTADO DE AUTODIAGNÓSTICO RIESGO DE FATALIDAD N°06: INCENDIO
B6: ELEMENTOS DEL CONTROL | I6: CUMPLIMIENTO GENERAL
I7: =AVERAGEIF(I14:I43,"<>N/A") -> 0.4
